Workbook

Sheet Instrucciones
A1: Tec Econ Challenge Formato operativo de evaluación
A4: Uso del archivo
A6: 1 | B6: Cada fila de las hojas “Evaluación escrita” y “Final presencial” corresponde a la evaluación de un jurado para un equipo.
A7: 2 | B7: Capture el folio del equipo y el nombre o identificador del jurado. No incluya el nombre de la preparatoria en la evaluación escrita cuando se utilice revisión anónima.
A8: 3 | B8: Asigne un puntaje a cada criterio dentro del máximo indicado. El nivel de desempeño se calcula automáticamente.
A9: 4 | B9: Registre observaciones breves, específicas y verificables. La conclusión elegida por el equipo no es un criterio de evaluación.
A10: 5 | B10: Una posible falta de integridad académica no se compensa reduciendo puntos. Marque la señal y descríbala para que la organización la revise por separado.
A11: 6 | B11: Cuando exista conflicto de interés, marque “Sí” y no finalice la evaluación hasta recibir indicaciones de la organización.
A12: 7 | B12: Las hojas de consolidación calculan promedios por folio. Capture los folios que participarán en cada etapa en la columna A de dichas hojas.
A14: Escala de desempeño
A16: Nivel | B16: Porcentaje del valor del criterio | C16: Interpretación operativa
A17: Excelente | B17: 90% a 100% | C17: Cumple plenamente el descriptor y presenta un desempeño sobresaliente.
A18: Bueno | B18: 75% a 89% | C18: Cumple adecuadamente el descriptor, con deficiencias menores.
A19: Suficiente | B19: 60% a 74% | C19: Cumple parcialmente; existen limitaciones relevantes.
A20: Insuficiente | B20: Menos de 60% | C20: No alcanza el desempeño mínimo esperado en el criterio.
A22: Parámetros de consolidación
A24: Número esperado de evaluaciones por equipo, etapa escrita | B24: 3
A25: Número esperado de evaluaciones por equipo, final presencial | B25: 3
A26: Correo de la organización | B26: marco.mendez@tec.mx

Sheet Evaluación escrita
A1: Evaluación del documento escrito
A3: Una fila por evaluación. Capture únicamente en las celdas blancas o amarillas; los niveles y totales se calculan automáticamente.
A5: Folio del equipo | B5: Jurado | C5: Fecha | D5: Conflicto de interés | E5: C1 Puntaje (máx. 15) | F5: C1 Nivel | G5: C2 Puntaje (máx. 25) | H5: C2 Nivel | I5: C3 Puntaje (máx. 25) | J5: C3 Nivel | K5: C4 Puntaje (máx. 20) | L5: C4 Nivel | M5: C5 Puntaje (máx. 15) | N5: C5 Nivel | O5: Total /100 | P5: Observaciones de la evaluación | Q5: Señal de integridad | R5: Descripción de la señal | S5: Estado | T5: Evaluación válida | U5: Preparación / campus (solo uso interno) | V5: Notas de coordinación
F6: =IF(E6="","",IF(E6/15>=0.9,"Excelente",IF(E6/15>=0.75,"Bueno",IF(E6/15>=0.6,"Suficiente","Insuficiente")))) | H6: =IF(G6="","",IF(G6/25>=0.9,"Excelente",IF(G6/25>=0.75,"Bueno",IF(G6/25>=0.6,"Suficiente","Insuficiente")))) | J6: =IF(I6="","",IF(I6/25>=0.9,"Excelente",IF(I6/25>=0.75,"Bueno",IF(I6/25>=0.6,"Suficiente","Insuficiente")))) | L6: =IF(K6="","",IF(K6/20>=0.9,"Excelente",IF(K6/20>=0.75,"Bueno",IF(K6/20>=0.6,"Suficiente","Insuficiente")))) | N6: =IF(M6="","",IF(M6/15>=0.9,"Excelente",IF(M6/15>=0.75,"Bueno",IF(M6/15>=0.6,"Suficiente","Insuficiente")))) | O6: =IF(COUNT(E6,G6,I6,K6,M6)<5,"",SUM(E6,G6,I6,K6,M6)) | T6: =IF(A6="","",IF(OR(D6="Sí",Q6="Sí",S6<>"Finalizada"),"No","Sí"))
F7: =IF(E7="","",IF(E7/15>=0.9,"Excelente",IF(E7/15>=0.75,"Bueno",IF(E7/15>=0.6,"Suficiente","Insuficiente")))) | H7: =IF(G7="","",IF(G7/25>=0.9,"Excelente",IF(G7/25>=0.75,"Bueno",IF(G7/25>=0.6,"Suficiente","Insuficiente")))) | J7: =IF(I7="","",IF(I7/25>=0.9,"Excelente",IF(I7/25>=0.75,"Bueno",IF(I7/25>=0.6,"Suficiente","Insuficiente")))) | L7: =IF(K7="","",IF(K7/20>=0.9,"Excelente",IF(K7/20>=0.75,"Bueno",IF(K7/20>=0.6,"Suficiente","Insuficiente")))) | N7: =IF(M7="","",IF(M7/15>=0.9,"Excelente",IF(M7/15>=0.75,"Bueno",IF(M7/15>=0.6,"Suficiente","Insuficiente")))) | O7: =IF(COUNT(E7,G7,I7,K7,M7)<5,"",SUM(E7,G7,I7,K7,M7)) | T7: =IF(A7="","",IF(OR(D7="Sí",Q7="Sí",S7<>"Finalizada"),"No","Sí"))
F8: =IF(E8="","",IF(E8/15>=0.9,"Excelente",IF(E8/15>=0.75,"Bueno",IF(E8/15>=0.6,"Suficiente","Insuficiente")))) | H8: =IF(G8="","",IF(G8/25>=0.9,"Excelente",IF(G8/25>=0.75,"Bueno",IF(G8/25>=0.6,"Suficiente","Insuficiente")))) | J8: =IF(I8="","",IF(I8/25>=0.9,"Excelente",IF(I8/25>=0.75,"Bueno",IF(I8/25>=0.6,"Suficiente","Insuficiente")))) | L8: =IF(K8="","",IF(K8/20>=0.9,"Excelente",IF(K8/20>=0.75,"Bueno",IF(K8/20>=0.6,"Suficiente","Insuficiente")))) | N8: =IF(M8="","",IF(M8/15>=0.9,"Excelente",IF(M8/15>=0.75,"Bueno",IF(M8/15>=0.6,"Suficiente","Insuficiente")))) | O8: =IF(COUNT(E8,G8,I8,K8,M8)<5,"",SUM(E8,G8,I8,K8,M8)) | T8: =IF(A8="","",IF(OR(D8="Sí",Q8="Sí",S8<>"Finalizada"),"No","Sí"))
F9: =IF(E9="","",IF(E9/15>=0.9,"Excelente",IF(E9/15>=0.75,"Bueno",IF(E9/15>=0.6,"Suficiente","Insuficiente")))) | H9: =IF(G9="","",IF(G9/25>=0.9,"Excelente",IF(G9/25>=0.75,"Bueno",IF(G9/25>=0.6,"Suficiente","Insuficiente")))) | J9: =IF(I9="","",IF(I9/25>=0.9,"Excelente",IF(I9/25>=0.75,"Bueno",IF(I9/25>=0.6,"Suficiente","Insuficiente")))) | L9: =IF(K9="","",IF(K9/20>=0.9,"Excelente",IF(K9/20>=0.75,"Bueno",IF(K9/20>=0.6,"Suficiente","Insuficiente")))) | N9: =IF(M9="","",IF(M9/15>=0.9,"Excelente",IF(M9/15>=0.75,"Bueno",IF(M9/15>=0.6,"Suficiente","Insuficiente")))) | O9: =IF(COUNT(E9,G9,I9,K9,M9)<5,"",SUM(E9,G9,I9,K9,M9)) | T9: =IF(A9="","",IF(OR(D9="Sí",Q9="Sí",S9<>"Finalizada"),"No","Sí"))
F10: =IF(E10="","",IF(E10/15>=0.9,"Excelente",IF(E10/15>=0.75,"Bueno",IF(E10/15>=0.6,"Suficiente","Insuficiente")))) | H10: =IF(G10="","",IF(G10/25>=0.9,"Excelente",IF(G10/25>=0.75,"Bueno",IF(G10/25>=0.6,"Suficiente","Insuficiente")))) | J10: =IF(I10="","",IF(I10/25>=0.9,"Excelente",IF(I10/25>=0.75,"Bueno",IF(I10/25>=0.6,"Suficiente","Insuficiente")))) | L10: =IF(K10="","",IF(K10/20>=0.9,"Excelente",IF(K10/20>=0.75,"Bueno",IF(K10/20>=0.6,"Suficiente","Insuficiente")))) | N10: =IF(M10="","",IF(M10/15>=0.9,"Excelente",IF(M10/15>=0.75,"Bueno",IF(M10/15>=0.6,"Suficiente","Insuficiente")))) | O10: =IF(COUNT(E10,G10,I10,K10,M10)<5,"",SUM(E10,G10,I10,K10,M10)) | T10: =IF(A10="","",IF(OR(D10="Sí",Q10="Sí",S10<>"Finalizada"),"No","Sí"))
F11: =IF(E11="","",IF(E11/15>=0.9,"Excelente",IF(E11/15>=0.75,"Bueno",IF(E11/15>=0.6,"Suficiente","Insuficiente")))) | H11: =IF(G11="","",IF(G11/25>=0.9,"Excelente",IF(G11/25>=0.75,"Bueno",IF(G11/25>=0.6,"Suficiente","Insuficiente")))) | J11: =IF(I11="","",IF(I11/25>=0.9,"Excelente",IF(I11/25>=0.75,"Bueno",IF(I11/25>=0.6,"Suficiente","Insuficiente")))) | L11: =IF(K11="","",IF(K11/20>=0.9,"Excelente",IF(K11/20>=0.75,"Bueno",IF(K11/20>=0.6,"Suficiente","Insuficiente")))) | N11: =IF(M11="","",IF(M11/15>=0.9,"Excelente",IF(M11/15>=0.75,"Bueno",IF(M11/15>=0.6,"Suficiente","Insuficiente")))) | O11: =IF(COUNT(E11,G11,I11,K11,M11)<5,"",SUM(E11,G11,I11,K11,M11)) | T11: =IF(A11="","",IF(OR(D11="Sí",Q11="Sí",S11<>"Finalizada"),"No","Sí"))
F12: =IF(E12="","",IF(E12/15>=0.9,"Excelente",IF(E12/15>=0.75,"Bueno",IF(E12/15>=0.6,"Suficiente","Insuficiente")))) | H12: =IF(G12="","",IF(G12/25>=0.9,"Excelente",IF(G12/25>=0.75,"Bueno",IF(G12/25>=0.6,"Suficiente","Insuficiente")))) | J12: =IF(I12="","",IF(I12/25>=0.9,"Excelente",IF(I12/25>=0.75,"Bueno",IF(I12/25>=0.6,"Suficiente","Insuficiente")))) | L12: =IF(K12="","",IF(K12/20>=0.9,"Excelente",IF(K12/20>=0.75,"Bueno",IF(K12/20>=0.6,"Suficiente","Insuficiente")))) | N12: =IF(M12="","",IF(M12/15>=0.9,"Excelente",IF(M12/15>=0.75,"Bueno",IF(M12/15>=0.6,"Suficiente","Insuficiente")))) | O12: =IF(COUNT(E12,G12,I12,K12,M12)<5,"",SUM(E12,G12,I12,K12,M12)) | T12: =IF(A12="","",IF(OR(D12="Sí",Q12="Sí",S12<>"Finalizada"),"No","Sí"))
F13: =IF(E13="","",IF(E13/15>=0.9,"Excelente",IF(E13/15>=0.75,"Bueno",IF(E13/15>=0.6,"Suficiente","Insuficiente")))) | H13: =IF(G13="","",IF(G13/25>=0.9,"Excelente",IF(G13/25>=0.75,"Bueno",IF(G13/25>=0.6,"Suficiente","Insuficiente")))) | J13: =IF(I13="","",IF(I13/25>=0.9,"Excelente",IF(I13/25>=0.75,"Bueno",IF(I13/25>=0.6,"Suficiente","Insuficiente")))) | L13: =IF(K13="","",IF(K13/20>=0.9,"Excelente",IF(K13/20>=0.75,"Bueno",IF(K13/20>=0.6,"Suficiente","Insuficiente")))) | N13: =IF(M13="","",IF(M13/15>=0.9,"Excelente",IF(M13/15>=0.75,"Bueno",IF(M13/15>=0.6,"Suficiente","Insuficiente")))) | O13: =IF(COUNT(E13,G13,I13,K13,M13)<5,"",SUM(E13,G13,I13,K13,M13)) | T13: =IF(A13="","",IF(OR(D13="Sí",Q13="Sí",S13<>"Finalizada"),"No","Sí"))
F14: =IF(E14="","",IF(E14/15>=0.9,"Excelente",IF(E14/15>=0.75,"Bueno",IF(E14/15>=0.6,"Suficiente","Insuficiente")))) | H14: =IF(G14="","",IF(G14/25>=0.9,"Excelente",IF(G14/25>=0.75,"Bueno",IF(G14/25>=0.6,"Suficiente","Insuficiente")))) | J14: =IF(I14="","",IF(I14/25>=0.9,"Excelente",IF(I14/25>=0.75,"Bueno",IF(I14/25>=0.6,"Suficiente","Insuficiente")))) | L14: =IF(K14="","",IF(K14/20>=0.9,"Excelente",IF(K14/20>=0.75,"Bueno",IF(K14/20>=0.6,"Suficiente","Insuficiente")))) | N14: =IF(M14="","",IF(M14/15>=0.9,"Excelente",IF(M14/15>=0.75,"Bueno",IF(M14/15>=0.6,"Suficiente","Insuficiente")))) | O14: =IF(COUNT(E14,G14,I14,K14,M14)<5,"",SUM(E14,G14,I14,K14,M14)) | T14: =IF(A14="","",IF(OR(D14="Sí",Q14="Sí",S14<>"Finalizada"),"No","Sí"))
F15: =IF(E15="","",IF(E15/15>=0.9,"Excelente",IF(E15/15>=0.75,"Bueno",IF(E15/15>=0.6,"Suficiente","Insuficiente")))) | H15: =IF(G15="","",IF(G15/25>=0.9,"Excelente",IF(G15/25>=0.75,"Bueno",IF(G15/25>=0.6,"Suficiente","Insuficiente")))) | J15: =IF(I15="","",IF(I15/25>=0.9,"Excelente",IF(I15/25>=0.75,"Bueno",IF(I15/25>=0.6,"Suficiente","Insuficiente")))) | L15: =IF(K15="","",IF(K15/20>=0.9,"Excelente",IF(K15/20>=0.75,"Bueno",IF(K15/20>=0.6,"Suficiente","Insuficiente")))) | N15: =IF(M15="","",IF(M15/15>=0.9,"Excelente",IF(M15/15>=0.75,"Bueno",IF(M15/15>=0.6,"Suficiente","Insuficiente")))) | O15: =IF(COUNT(E15,G15,I15,K15,M15)<5,"",SUM(E15,G15,I15,K15,M15)) | T15: =IF(A15="","",IF(OR(D15="Sí",Q15="Sí",S15<>"Finalizada"),"No","Sí"))
F16: =IF(E16="","",IF(E16/15>=0.9,"Excelente",IF(E16/15>=0.75,"Bueno",IF(E16/15>=0.6,"Suficiente","Insuficiente")))) | H16: =IF(G16="","",IF(G16/25>=0.9,"Excelente",IF(G16/25>=0.75,"Bueno",IF(G16/25>=0.6,"Suficiente","Insuficiente")))) | J16: =IF(I16="","",IF(I16/25>=0.9,"Excelente",IF(I16/25>=0.75,"Bueno",IF(I16/25>=0.6,"Suficiente","Insuficiente")))) | L16: =IF(K16="","",IF(K16/20>=0.9,"Excelente",IF(K16/20>=0.75,"Bueno",IF(K16/20>=0.6,"Suficiente","Insuficiente")))) | N16: =IF(M16="","",IF(M16/15>=0.9,"Excelente",IF(M16/15>=0.75,"Bueno",IF(M16/15>=0.6,"Suficiente","Insuficiente")))) | O16: =IF(COUNT(E16,G16,I16,K16,M16)<5,"",SUM(E16,G16,I16,K16,M16)) | T16: =IF(A16="","",IF(OR(D16="Sí",Q16="Sí",S16<>"Finalizada"),"No","Sí"))
F17: =IF(E17="","",IF(E17/15>=0.9,"Excelente",IF(E17/15>=0.75,"Bueno",IF(E17/15>=0.6,"Suficiente","Insuficiente")))) | H17: =IF(G17="","",IF(G17/25>=0.9,"Excelente",IF(G17/25>=0.75,"Bueno",IF(G17/25>=0.6,"Suficiente","Insuficiente")))) | J17: =IF(I17="","",IF(I17/25>=0.9,"Excelente",IF(I17/25>=0.75,"Bueno",IF(I17/25>=0.6,"Suficiente","Insuficiente")))) | L17: =IF(K17="","",IF(K17/20>=0.9,"Excelente",IF(K17/20>=0.75,"Bueno",IF(K17/20>=0.6,"Suficiente","Insuficiente")))) | N17: =IF(M17="","",IF(M17/15>=0.9,"Excelente",IF(M17/15>=0.75,"Bueno",IF(M17/15>=0.6,"Suficiente","Insuficiente")))) | O17: =IF(COUNT(E17,G17,I17,K17,M17)<5,"",SUM(E17,G17,I17,K17,M17)) | T17: =IF(A17="","",IF(OR(D17="Sí",Q17="Sí",S17<>"Finalizada"),"No","Sí"))
... F125: =IF(E125="","",IF(E125/15>=0.9,"Excelente",IF(E125/15>=0.75,"Bueno",IF(E125/15>=0.6,"Suficiente","Insuficiente")))) | H125: =IF(G125="","",IF(G125/25>=0.9,"Excelente",IF(G125/25>=0.75,"Bueno",IF(G125/25>=0.6,"Suficiente","Insuficiente")))) | J125: =IF(I125="","",IF(I125/25>=0.9,"Excelente",IF(I125/25>=0.75,"Bueno",IF(I125/25>=0.6,"Suficiente","Insuficiente")))) | L125: =IF(K125="","",IF(K125/20>=0.9,"Excelente",IF(K125/20>=0.75,"Bueno",IF(K125/20>=0.6,"Suficiente","Insuficiente")))) | N125: =IF(M125="","",IF(M125/15>=0.9,"Excelente",IF(M125/15>=0.75,"Bueno",IF(M125/15>=0.6,"Suficiente","Insuficiente")))) | O125: =IF(COUNT(E125,G125,I125,K125,M125)<5,"",SUM(E125,G125,I125,K125,M125)) | T125: =IF(A125="","",IF(OR(D125="Sí",Q125="Sí",S125<>"Finalizada"),"No","Sí"))
A128: Referencia rápida de criterios
A129: Criterio | B129: Máximo | C129: Pregunta orientadora | D129: Observación
A130: C1. Comprensión y delimitación del problema económico | B130: 15 | C130: ¿El equipo identifica con precisión la pregunta central, los actores, las variables y el alcance del problema? | D130: Consulte la rúbrica oficial para los descriptores completos.
A131: C2. Coherencia entre teoría, datos y conclusiones | B131: 25 | C131: ¿Los conceptos económicos y los datos se conectan mediante una cadena de razonamiento consistente? | D131: Consulte la rúbrica oficial para los descriptores completos.
A132: C3. Calidad del análisis de datos | B132: 25 | C132: ¿El equipo selecciona, procesa, presenta e interpreta adecuadamente los datos pertinentes? | D132: Consulte la rúbrica oficial para los descriptores completos.
A133: C4. Uso de evidencia, fuentes y reconocimiento de limitaciones | B133: 20 | C133: ¿El equipo integra fuentes diversas, distingue su naturaleza y reconoce las limitaciones de la evidencia? | D133: Consulte la rúbrica oficial para los descriptores completos.
A134: C5. Claridad, estructura y calidad de la comunicación escrita | B134: 15 | C134: ¿El documento presenta el análisis de manera ordenada, precisa y comprensible? | D134: Consulte la rúbrica oficial para los descriptores completos.

Sheet Final presencial
A1: Evaluación de la final presencial
A3: Una fila por evaluación. Capture únicamente en las celdas blancas o amarillas; los niveles y totales se calculan automáticamente.
A5: Folio del equipo | B5: Jurado | C5: Fecha | D5: Conflicto de interés | E5: C1 Puntaje (máx. 25) | F5: C1 Nivel | G5: C2 Puntaje (máx. 25) | H5: C2 Nivel | I5: C3 Puntaje (máx. 20) | J5: C3 Nivel | K5: C4 Puntaje (máx. 20) | L5: C4 Nivel | M5: C5 Puntaje (máx. 10) | N5: C5 Nivel | O5: Total /100 | P5: Observaciones de la evaluación | Q5: Señal de integridad | R5: Descripción de la señal | S5: Estado | T5: Evaluación válida | U5: Preparación / campus (solo uso interno) | V5: Notas de coordinación
F6: =IF(E6="","",IF(E6/25>=0.9,"Excelente",IF(E6/25>=0.75,"Bueno",IF(E6/25>=0.6,"Suficiente","Insuficiente")))) | H6: =IF(G6="","",IF(G6/25>=0.9,"Excelente",IF(G6/25>=0.75,"Bueno",IF(G6/25>=0.6,"Suficiente","Insuficiente")))) | J6: =IF(I6="","",IF(I6/20>=0.9,"Excelente",IF(I6/20>=0.75,"Bueno",IF(I6/20>=0.6,"Suficiente","Insuficiente")))) | L6: =IF(K6="","",IF(K6/20>=0.9,"Excelente",IF(K6/20>=0.75,"Bueno",IF(K6/20>=0.6,"Suficiente","Insuficiente")))) | N6: =IF(M6="","",IF(M6/10>=0.9,"Excelente",IF(M6/10>=0.75,"Bueno",IF(M6/10>=0.6,"Suficiente","Insuficiente")))) | O6: =IF(COUNT(E6,G6,I6,K6,M6)<5,"",SUM(E6,G6,I6,K6,M6)) | T6: =IF(A6="","",IF(OR(D6="Sí",Q6="Sí",S6<>"Finalizada"),"No","Sí"))
F7: =IF(E7="","",IF(E7/25>=0.9,"Excelente",IF(E7/25>=0.75,"Bueno",IF(E7/25>=0.6,"Suficiente","Insuficiente")))) | H7: =IF(G7="","",IF(G7/25>=0.9,"Excelente",IF(G7/25>=0.75,"Bueno",IF(G7/25>=0.6,"Suficiente","Insuficiente")))) | J7: =IF(I7="","",IF(I7/20>=0.9,"Excelente",IF(I7/20>=0.75,"Bueno",IF(I7/20>=0.6,"Suficiente","Insuficiente")))) | L7: =IF(K7="","",IF(K7/20>=0.9,"Excelente",IF(K7/20>=0.75,"Bueno",IF(K7/20>=0.6,"Suficiente","Insuficiente")))) | N7: =IF(M7="","",IF(M7/10>=0.9,"Excelente",IF(M7/10>=0.75,"Bueno",IF(M7/10>=0.6,"Suficiente","Insuficiente")))) | O7: =IF(COUNT(E7,G7,I7,K7,M7)<5,"",SUM(E7,G7,I7,K7,M7)) | T7: =IF(A7="","",IF(OR(D7="Sí",Q7="Sí",S7<>"Finalizada"),"No","Sí"))
F8: =IF(E8="","",IF(E8/25>=0.9,"Excelente",IF(E8/25>=0.75,"Bueno",IF(E8/25>=0.6,"Suficiente","Insuficiente")))) | H8: =IF(G8="","",IF(G8/25>=0.9,"Excelente",IF(G8/25>=0.75,"Bueno",IF(G8/25>=0.6,"Suficiente","Insuficiente")))) | J8: =IF(I8="","",IF(I8/20>=0.9,"Excelente",IF(I8/20>=0.75,"Bueno",IF(I8/20>=0.6,"Suficiente","Insuficiente")))) | L8: =IF(K8="","",IF(K8/20>=0.9,"Excelente",IF(K8/20>=0.75,"Bueno",IF(K8/20>=0.6,"Suficiente","Insuficiente")))) | N8: =IF(M8="","",IF(M8/10>=0.9,"Excelente",IF(M8/10>=0.75,"Bueno",IF(M8/10>=0.6,"Suficiente","Insuficiente")))) | O8: =IF(COUNT(E8,G8,I8,K8,M8)<5,"",SUM(E8,G8,I8,K8,M8)) | T8: =IF(A8="","",IF(OR(D8="Sí",Q8="Sí",S8<>"Finalizada"),"No","Sí"))
F9: =IF(E9="","",IF(E9/25>=0.9,"Excelente",IF(E9/25>=0.75,"Bueno",IF(E9/25>=0.6,"Suficiente","Insuficiente")))) | H9: =IF(G9="","",IF(G9/25>=0.9,"Excelente",IF(G9/25>=0.75,"Bueno",IF(G9/25>=0.6,"Suficiente","Insuficiente")))) | J9: =IF(I9="","",IF(I9/20>=0.9,"Excelente",IF(I9/20>=0.75,"Bueno",IF(I9/20>=0.6,"Suficiente","Insuficiente")))) | L9: =IF(K9="","",IF(K9/20>=0.9,"Excelente",IF(K9/20>=0.75,"Bueno",IF(K9/20>=0.6,"Suficiente","Insuficiente")))) | N9: =IF(M9="","",IF(M9/10>=0.9,"Excelente",IF(M9/10>=0.75,"Bueno",IF(M9/10>=0.6,"Suficiente","Insuficiente")))) | O9: =IF(COUNT(E9,G9,I9,K9,M9)<5,"",SUM(E9,G9,I9,K9,M9)) | T9: =IF(A9="","",IF(OR(D9="Sí",Q9="Sí",S9<>"Finalizada"),"No","Sí"))
F10: =IF(E10="","",IF(E10/25>=0.9,"Excelente",IF(E10/25>=0.75,"Bueno",IF(E10/25>=0.6,"Suficiente","Insuficiente")))) | H10: =IF(G10="","",IF(G10/25>=0.9,"Excelente",IF(G10/25>=0.75,"Bueno",IF(G10/25>=0.6,"Suficiente","Insuficiente")))) | J10: =IF(I10="","",IF(I10/20>=0.9,"Excelente",IF(I10/20>=0.75,"Bueno",IF(I10/20>=0.6,"Suficiente","Insuficiente")))) | L10: =IF(K10="","",IF(K10/20>=0.9,"Excelente",IF(K10/20>=0.75,"Bueno",IF(K10/20>=0.6,"Suficiente","Insuficiente")))) | N10: =IF(M10="","",IF(M10/10>=0.9,"Excelente",IF(M10/10>=0.75,"Bueno",IF(M10/10>=0.6,"Suficiente","Insuficiente")))) | O10: =IF(COUNT(E10,G10,I10,K10,M10)<5,"",SUM(E10,G10,I10,K10,M10)) | T10: =IF(A10="","",IF(OR(D10="Sí",Q10="Sí",S10<>"Finalizada"),"No","Sí"))
F11: =IF(E11="","",IF(E11/25>=0.9,"Excelente",IF(E11/25>=0.75,"Bueno",IF(E11/25>=0.6,"Suficiente","Insuficiente")))) | H11: =IF(G11="","",IF(G11/25>=0.9,"Excelente",IF(G11/25>=0.75,"Bueno",IF(G11/25>=0.6,"Suficiente","Insuficiente")))) | J11: =IF(I11="","",IF(I11/20>=0.9,"Excelente",IF(I11/20>=0.75,"Bueno",IF(I11/20>=0.6,"Suficiente","Insuficiente")))) | L11: =IF(K11="","",IF(K11/20>=0.9,"Excelente",IF(K11/20>=0.75,"Bueno",IF(K11/20>=0.6,"Suficiente","Insuficiente")))) | N11: =IF(M11="","",IF(M11/10>=0.9,"Excelente",IF(M11/10>=0.75,"Bueno",IF(M11/10>=0.6,"Suficiente","Insuficiente")))) | O11: =IF(COUNT(E11,G11,I11,K11,M11)<5,"",SUM(E11,G11,I11,K11,M11)) | T11: =IF(A11="","",IF(OR(D11="Sí",Q11="Sí",S11<>"Finalizada"),"No","Sí"))
F12: =IF(E12="","",IF(E12/25>=0.9,"Excelente",IF(E12/25>=0.75,"Bueno",IF(E12/25>=0.6,"Suficiente","Insuficiente")))) | H12: =IF(G12="","",IF(G12/25>=0.9,"Excelente",IF(G12/25>=0.75,"Bueno",IF(G12/25>=0.6,"Suficiente","Insuficiente")))) | J12: =IF(I12="","",IF(I12/20>=0.9,"Excelente",IF(I12/20>=0.75,"Bueno",IF(I12/20>=0.6,"Suficiente","Insuficiente")))) | L12: =IF(K12="","",IF(K12/20>=0.9,"Excelente",IF(K12/20>=0.75,"Bueno",IF(K12/20>=0.6,"Suficiente","Insuficiente")))) | N12: =IF(M12="","",IF(M12/10>=0.9,"Excelente",IF(M12/10>=0.75,"Bueno",IF(M12/10>=0.6,"Suficiente","Insuficiente")))) | O12: =IF(COUNT(E12,G12,I12,K12,M12)<5,"",SUM(E12,G12,I12,K12,M12)) | T12: =IF(A12="","",IF(OR(D12="Sí",Q12="Sí",S12<>"Finalizada"),"No","Sí"))
F13: =IF(E13="","",IF(E13/25>=0.9,"Excelente",IF(E13/25>=0.75,"Bueno",IF(E13/25>=0.6,"Suficiente","Insuficiente")))) | H13: =IF(G13="","",IF(G13/25>=0.9,"Excelente",IF(G13/25>=0.75,"Bueno",IF(G13/25>=0.6,"Suficiente","Insuficiente")))) | J13: =IF(I13="","",IF(I13/20>=0.9,"Excelente",IF(I13/20>=0.75,"Bueno",IF(I13/20>=0.6,"Suficiente","Insuficiente")))) | L13: =IF(K13="","",IF(K13/20>=0.9,"Excelente",IF(K13/20>=0.75,"Bueno",IF(K13/20>=0.6,"Suficiente","Insuficiente")))) | N13: =IF(M13="","",IF(M13/10>=0.9,"Excelente",IF(M13/10>=0.75,"Bueno",IF(M13/10>=0.6,"Suficiente","Insuficiente")))) | O13: =IF(COUNT(E13,G13,I13,K13,M13)<5,"",SUM(E13,G13,I13,K13,M13)) | T13: =IF(A13="","",IF(OR(D13="Sí",Q13="Sí",S13<>"Finalizada"),"No","Sí"))
F14: =IF(E14="","",IF(E14/25>=0.9,"Excelente",IF(E14/25>=0.75,"Bueno",IF(E14/25>=0.6,"Suficiente","Insuficiente")))) | H14: =IF(G14="","",IF(G14/25>=0.9,"Excelente",IF(G14/25>=0.75,"Bueno",IF(G14/25>=0.6,"Suficiente","Insuficiente")))) | J14: =IF(I14="","",IF(I14/20>=0.9,"Excelente",IF(I14/20>=0.75,"Bueno",IF(I14/20>=0.6,"Suficiente","Insuficiente")))) | L14: =IF(K14="","",IF(K14/20>=0.9,"Excelente",IF(K14/20>=0.75,"Bueno",IF(K14/20>=0.6,"Suficiente","Insuficiente")))) | N14: =IF(M14="","",IF(M14/10>=0.9,"Excelente",IF(M14/10>=0.75,"Bueno",IF(M14/10>=0.6,"Suficiente","Insuficiente")))) | O14: =IF(COUNT(E14,G14,I14,K14,M14)<5,"",SUM(E14,G14,I14,K14,M14)) | T14: =IF(A14="","",IF(OR(D14="Sí",Q14="Sí",S14<>"Finalizada"),"No","Sí"))
F15: =IF(E15="","",IF(E15/25>=0.9,"Excelente",IF(E15/25>=0.75,"Bueno",IF(E15/25>=0.6,"Suficiente","Insuficiente")))) | H15: =IF(G15="","",IF(G15/25>=0.9,"Excelente",IF(G15/25>=0.75,"Bueno",IF(G15/25>=0.6,"Suficiente","Insuficiente")))) | J15: =IF(I15="","",IF(I15/20>=0.9,"Excelente",IF(I15/20>=0.75,"Bueno",IF(I15/20>=0.6,"Suficiente","Insuficiente")))) | L15: =IF(K15="","",IF(K15/20>=0.9,"Excelente",IF(K15/20>=0.75,"Bueno",IF(K15/20>=0.6,"Suficiente","Insuficiente")))) | N15: =IF(M15="","",IF(M15/10>=0.9,"Excelente",IF(M15/10>=0.75,"Bueno",IF(M15/10>=0.6,"Suficiente","Insuficiente")))) | O15: =IF(COUNT(E15,G15,I15,K15,M15)<5,"",SUM(E15,G15,I15,K15,M15)) | T15: =IF(A15="","",IF(OR(D15="Sí",Q15="Sí",S15<>"Finalizada"),"No","Sí"))
F16: =IF(E16="","",IF(E16/25>=0.9,"Excelente",IF(E16/25>=0.75,"Bueno",IF(E16/25>=0.6,"Suficiente","Insuficiente")))) | H16: =IF(G16="","",IF(G16/25>=0.9,"Excelente",IF(G16/25>=0.75,"Bueno",IF(G16/25>=0.6,"Suficiente","Insuficiente")))) | J16: =IF(I16="","",IF(I16/20>=0.9,"Excelente",IF(I16/20>=0.75,"Bueno",IF(I16/20>=0.6,"Suficiente","Insuficiente")))) | L16: =IF(K16="","",IF(K16/20>=0.9,"Excelente",IF(K16/20>=0.75,"Bueno",IF(K16/20>=0.6,"Suficiente","Insuficiente")))) | N16: =IF(M16="","",IF(M16/10>=0.9,"Excelente",IF(M16/10>=0.75,"Bueno",IF(M16/10>=0.6,"Suficiente","Insuficiente")))) | O16: =IF(COUNT(E16,G16,I16,K16,M16)<5,"",SUM(E16,G16,I16,K16,M16)) | T16: =IF(A16="","",IF(OR(D16="Sí",Q16="Sí",S16<>"Finalizada"),"No","Sí"))
F17: =IF(E17="","",IF(E17/25>=0.9,"Excelente",IF(E17/25>=0.75,"Bueno",IF(E17/25>=0.6,"Suficiente","Insuficiente")))) | H17: =IF(G17="","",IF(G17/25>=0.9,"Excelente",IF(G17/25>=0.75,"Bueno",IF(G17/25>=0.6,"Suficiente","Insuficiente")))) | J17: =IF(I17="","",IF(I17/20>=0.9,"Excelente",IF(I17/20>=0.75,"Bueno",IF(I17/20>=0.6,"Suficiente","Insuficiente")))) | L17: =IF(K17="","",IF(K17/20>=0.9,"Excelente",IF(K17/20>=0.75,"Bueno",IF(K17/20>=0.6,"Suficiente","Insuficiente")))) | N17: =IF(M17="","",IF(M17/10>=0.9,"Excelente",IF(M17/10>=0.75,"Bueno",IF(M17/10>=0.6,"Suficiente","Insuficiente")))) | O17: =IF(COUNT(E17,G17,I17,K17,M17)<5,"",SUM(E17,G17,I17,K17,M17)) | T17: =IF(A17="","",IF(OR(D17="Sí",Q17="Sí",S17<>"Finalizada"),"No","Sí"))
... F125: =IF(E125="","",IF(E125/25>=0.9,"Excelente",IF(E125/25>=0.75,"Bueno",IF(E125/25>=0.6,"Suficiente","Insuficiente")))) | H125: =IF(G125="","",IF(G125/25>=0.9,"Excelente",IF(G125/25>=0.75,"Bueno",IF(G125/25>=0.6,"Suficiente","Insuficiente")))) | J125: =IF(I125="","",IF(I125/20>=0.9,"Excelente",IF(I125/20>=0.75,"Bueno",IF(I125/20>=0.6,"Suficiente","Insuficiente")))) | L125: =IF(K125="","",IF(K125/20>=0.9,"Excelente",IF(K125/20>=0.75,"Bueno",IF(K125/20>=0.6,"Suficiente","Insuficiente")))) | N125: =IF(M125="","",IF(M125/10>=0.9,"Excelente",IF(M125/10>=0.75,"Bueno",IF(M125/10>=0.6,"Suficiente","Insuficiente")))) | O125: =IF(COUNT(E125,G125,I125,K125,M125)<5,"",SUM(E125,G125,I125,K125,M125)) | T125: =IF(A125="","",IF(OR(D125="Sí",Q125="Sí",S125<>"Finalizada"),"No","Sí"))
A128: Referencia rápida de criterios
A129: Criterio | B129: Máximo | C129: Pregunta orientadora | D129: Observación
A130: C1. Solidez y coherencia del argumento | B130: 25 | C130: ¿La exposición presenta una postura clara, consistente y debidamente justificada? | D130: Consulte la rúbrica oficial para los descriptores completos.
A131: C2. Uso de evidencia y respuesta a objeciones | B131: 25 | C131: ¿El equipo utiliza evidencia pertinente y atiende objeciones o explicaciones alternativas? | D131: Consulte la rúbrica oficial para los descriptores completos.
A132: C3. Claridad y estructura de la presentación | B132: 20 | C132: ¿La exposición prioriza la información esencial, respeta el tiempo y utiliza apoyos legibles? | D132: Consulte la rúbrica oficial para los descriptores completos.
A133: C4. Defensa ante las preguntas del jurado | B133: 20 | C133: ¿El equipo comprende su análisis y responde de manera directa, razonada y consistente? | D133: Consulte la rúbrica oficial para los descriptores completos.
A134: C5. Participación y coordinación del equipo | B134: 10 | C134: ¿El equipo distribuye la participación y actúa de manera coordinada? | D134: Consulte la rúbrica oficial para los descriptores completos.

Sheet Consolidado escrita
A1: Consolidado escrita | M1: Criterios y máximos
M2: Clave | N2: Criterio | O2: Máximo
A3: Capture en la columna A los folios que participan en esta etapa. Los demás campos se calculan automáticamente a partir de las evaluaciones válidas. | M3: C1 | N3: Comprensión y delimitación del problema económico | O3: 15
M4: C2 | N4: Coherencia entre teoría, datos y conclusiones | O4: 25
A5: Folio del equipo | B5: Evaluaciones válidas | C5: Promedio total | D5: Promedio C1 | E5: Promedio C2 | F5: Promedio C3 | G5: Promedio C4 | H5: Promedio C5 | I5: Evaluación completa | J5: Lugar preliminar | K5: Observación de coordinación | M5: C3 | N5: Calidad del análisis de datos | O5: 25
B6: =IF(A6="","",COUNTIFS('Evaluación escrita'!$A$6:$A$125,A6,'Evaluación escrita'!$T$6:$T$125,"Sí")) | C6: =IF(A6="","",IFERROR(SUMIFS('Evaluación escrita'!$O$6:$O$125,'Evaluación escrita'!$A$6:$A$125,A6,'Evaluación escrita'!$T$6:$T$125,"Sí")/B6,"")) | D6: =IF(A6="","",IFERROR(SUMIFS('Evaluación escrita'!$E$6:$E$125,'Evaluación escrita'!$A$6:$A$125,A6,'Evaluación escrita'!$T$6:$T$125,"Sí")/B6,"")) | E6: =IF(A6="","",IFERROR(SUMIFS('Evaluación escrita'!$G$6:$G$125,'Evaluación escrita'!$A$6:$A$125,A6,'Evaluación escrita'!$T$6:$T$125,"Sí")/B6,"")) | F6: =IF(A6="","",IFERROR(SUMIFS('Evaluación escrita'!$I$6:$I$125,'Evaluación escrita'!$A$6:$A$125,A6,'Evaluación escrita'!$T$6:$T$125,"Sí")/B6,"")) | G6: =IF(A6="","",IFERROR(SUMIFS('Evaluación escrita'!$K$6:$K$125,'Evaluación escrita'!$A$6:$A$125,A6,'Evaluación escrita'!$T$6:$T$125,"Sí")/B6,"")) | H6: =IF(A6="","",IFERROR(SUMIFS('Evaluación escrita'!$M$6:$M$125,'Evaluación escrita'!$A$6:$A$125,A6,'Evaluación escrita'!$T$6:$T$125,"Sí")/B6,"")) | I6: =IF(A6="","",IF(B6>=Instrucciones!$B24,"Sí","Pendiente")) | J6: =IF(C6="","",RANK(C6,$C$6:$C$65,0)) | M6: C4 | N6: Uso de evidencia, fuentes y reconocimiento de limitaciones | O6: 20
B7: =IF(A7="","",COUNTIFS('Evaluación escrita'!$A$6:$A$125,A7,'Evaluación escrita'!$T$6:$T$125,"Sí")) | C7: =IF(A7="","",IFERROR(SUMIFS('Evaluación escrita'!$O$6:$O$125,'Evaluación escrita'!$A$6:$A$125,A7,'Evaluación escrita'!$T$6:$T$125,"Sí")/B7,"")) | D7: =IF(A7="","",IFERROR(SUMIFS('Evaluación escrita'!$E$6:$E$125,'Evaluación escrita'!$A$6:$A$125,A7,'Evaluación escrita'!$T$6:$T$125,"Sí")/B7,"")) | E7: =IF(A7="","",IFERROR(SUMIFS('Evaluación escrita'!$G$6:$G$125,'Evaluación escrita'!$A$6:$A$125,A7,'Evaluación escrita'!$T$6:$T$125,"Sí")/B7,"")) | F7: =IF(A7="","",IFERROR(SUMIFS('Evaluación escrita'!$I$6:$I$125,'Evaluación escrita'!$A$6:$A$125,A7,'Evaluación escrita'!$T$6:$T$125,"Sí")/B7,"")) | G7: =IF(A7="","",IFERROR(SUMIFS('Evaluación escrita'!$K$6:$K$125,'Evaluación escrita'!$A$6:$A$125,A7,'Evaluación escrita'!$T$6:$T$125,"Sí")/B7,"")) | H7: =IF(A7="","",IFERROR(SUMIFS('Evaluación escrita'!$M$6:$M$125,'Evaluación escrita'!$A$6:$A$125,A7,'Evaluación escrita'!$T$6:$T$125,"Sí")/B7,"")) | I7: =IF(A7="","",IF(B7>=Instrucciones!$B25,"Sí","Pendiente")) | J7: =IF(C7="","",RANK(C7,$C$6:$C$65,0)) | M7: C5 | N7: Claridad, estructura y calidad de la comunicación escrita | O7: 15
B8: =IF(A8="","",COUNTIFS('Evaluación escrita'!$A$6:$A$125,A8,'Evaluación escrita'!$T$6:$T$125,"Sí")) | C8: =IF(A8="","",IFERROR(SUMIFS('Evaluación escrita'!$O$6:$O$125,'Evaluación escrita'!$A$6:$A$125,A8,'Evaluación escrita'!$T$6:$T$125,"Sí")/B8,"")) | D8: =IF(A8="","",IFERROR(SUMIFS('Evaluación escrita'!$E$6:$E$125,'Evaluación escrita'!$A$6:$A$125,A8,'Evaluación escrita'!$T$6:$T$125,"Sí")/B8,"")) | E8: =IF(A8="","",IFERROR(SUMIFS('Evaluación escrita'!$G$6:$G$125,'Evaluación escrita'!$A$6:$A$125,A8,'Evaluación escrita'!$T$6:$T$125,"Sí")/B8,"")) | F8: =IF(A8="","",IFERROR(SUMIFS('Evaluación escrita'!$I$6:$I$125,'Evaluación escrita'!$A$6:$A$125,A8,'Evaluación escrita'!$T$6:$T$125,"Sí")/B8,"")) | G8: =IF(A8="","",IFERROR(SUMIFS('Evaluación escrita'!$K$6:$K$125,'Evaluación escrita'!$A$6:$A$125,A8,'Evaluación escrita'!$T$6:$T$125,"Sí")/B8,"")) | H8: =IF(A8="","",IFERROR(SUMIFS('Evaluación escrita'!$M$6:$M$125,'Evaluación escrita'!$A$6:$A$125,A8,'Evaluación escrita'!$T$6:$T$125,"Sí")/B8,"")) | I8: =IF(A8="","",IF(B8>=Instrucciones!$B26,"Sí","Pendiente")) | J8: =IF(C8="","",RANK(C8,$C$6:$C$65,0))
B9: =IF(A9="","",COUNTIFS('Evaluación escrita'!$A$6:$A$125,A9,'Evaluación escrita'!$T$6:$T$125,"Sí")) | C9: =IF(A9="","",IFERROR(SUMIFS('Evaluación escrita'!$O$6:$O$125,'Evaluación escrita'!$A$6:$A$125,A9,'Evaluación escrita'!$T$6:$T$125,"Sí")/B9,"")) | D9: =IF(A9="","",IFERROR(SUMIFS('Evaluación escrita'!$E$6:$E$125,'Evaluación escrita'!$A$6:$A$125,A9,'Evaluación escrita'!$T$6:$T$125,"Sí")/B9,"")) | E9: =IF(A9="","",IFERROR(SUMIFS('Evaluación escrita'!$G$6:$G$125,'Evaluación escrita'!$A$6:$A$125,A9,'Evaluación escrita'!$T$6:$T$125,"Sí")/B9,"")) | F9: =IF(A9="","",IFERROR(SUMIFS('Evaluación escrita'!$I$6:$I$125,'Evaluación escrita'!$A$6:$A$125,A9,'Evaluación escrita'!$T$6:$T$125,"Sí")/B9,"")) | G9: =IF(A9="","",IFERROR(SUMIFS('Evaluación escrita'!$K$6:$K$125,'Evaluación escrita'!$A$6:$A$125,A9,'Evaluación escrita'!$T$6:$T$125,"Sí")/B9,"")) | H9: =IF(A9="","",IFERROR(SUMIFS('Evaluación escrita'!$M$6:$M$125,'Evaluación escrita'!$A$6:$A$125,A9,'Evaluación escrita'!$T$6:$T$125,"Sí")/B9,"")) | I9: =IF(A9="","",IF(B9>=Instrucciones!$B27,"Sí","Pendiente")) | J9: =IF(C9="","",RANK(C9,$C$6:$C$65,0))
B10: =IF(A10="","",COUNTIFS('Evaluación escrita'!$A$6:$A$125,A10,'Evaluación escrita'!$T$6:$T$125,"Sí")) | C10: =IF(A10="","",IFERROR(SUMIFS('Evaluación escrita'!$O$6:$O$125,'Evaluación escrita'!$A$6:$A$125,A10,'Evaluación escrita'!$T$6:$T$125,"Sí")/B10,"")) | D10: =IF(A10="","",IFERROR(SUMIFS('Evaluación escrita'!$E$6:$E$125,'Evaluación escrita'!$A$6:$A$125,A10,'Evaluación escrita'!$T$6:$T$125,"Sí")/B10,"")) | E10: =IF(A10="","",IFERROR(SUMIFS('Evaluación escrita'!$G$6:$G$125,'Evaluación escrita'!$A$6:$A$125,A10,'Evaluación escrita'!$T$6:$T$125,"Sí")/B10,"")) | F10: =IF(A10="","",IFERROR(SUMIFS('Evaluación escrita'!$I$6:$I$125,'Evaluación escrita'!$A$6:$A$125,A10,'Evaluación escrita'!$T$6:$T$125,"Sí")/B10,"")) | G10: =IF(A10="","",IFERROR(SUMIFS('Evaluación escrita'!$K$6:$K$125,'Evaluación escrita'!$A$6:$A$125,A10,'Evaluación escrita'!$T$6:$T$125,"Sí")/B10,"")) | H10: =IF(A10="","",IFERROR(SUMIFS('Evaluación escrita'!$M$6:$M$125,'Evaluación escrita'!$A$6:$A$125,A10,'Evaluación escrita'!$T$6:$T$125,"Sí")/B10,"")) | I10: =IF(A10="","",IF(B10>=Instrucciones!$B28,"Sí","Pendiente")) | J10: =IF(C10="","",RANK(C10,$C$6:$C$65,0))
B11: =IF(A11="","",COUNTIFS('Evaluación escrita'!$A$6:$A$125,A11,'Evaluación escrita'!$T$6:$T$125,"Sí")) | C11: =IF(A11="","",IFERROR(SUMIFS('Evaluación escrita'!$O$6:$O$125,'Evaluación escrita'!$A$6:$A$125,A11,'Evaluación escrita'!$T$6:$T$125,"Sí")/B11,"")) | D11: =IF(A11="","",IFERROR(SUMIFS('Evaluación escrita'!$E$6:$E$125,'Evaluación escrita'!$A$6:$A$125,A11,'Evaluación escrita'!$T$6:$T$125,"Sí")/B11,"")) | E11: =IF(A11="","",IFERROR(SUMIFS('Evaluación escrita'!$G$6:$G$125,'Evaluación escrita'!$A$6:$A$125,A11,'Evaluación escrita'!$T$6:$T$125,"Sí")/B11,"")) | F11: =IF(A11="","",IFERROR(SUMIFS('Evaluación escrita'!$I$6:$I$125,'Evaluación escrita'!$A$6:$A$125,A11,'Evaluación escrita'!$T$6:$T$125,"Sí")/B11,"")) | G11: =IF(A11="","",IFERROR(SUMIFS('Evaluación escrita'!$K$6:$K$125,'Evaluación escrita'!$A$6:$A$125,A11,'Evaluación escrita'!$T$6:$T$125,"Sí")/B11,"")) | H11: =IF(A11="","",IFERROR(SUMIFS('Evaluación escrita'!$M$6:$M$125,'Evaluación escrita'!$A$6:$A$125,A11,'Evaluación escrita'!$T$6:$T$125,"Sí")/B11,"")) | I11: =IF(A11="","",IF(B11>=Instrucciones!$B29,"Sí","Pendiente")) | J11: =IF(C11="","",RANK(C11,$C$6:$C$65,0))
B12: =IF(A12="","",COUNTIFS('Evaluación escrita'!$A$6:$A$125,A12,'Evaluación escrita'!$T$6:$T$125,"Sí")) | C12: =IF(A12="","",IFERROR(SUMIFS('Evaluación escrita'!$O$6:$O$125,'Evaluación escrita'!$A$6:$A$125,A12,'Evaluación escrita'!$T$6:$T$125,"Sí")/B12,"")) | D12: =IF(A12="","",IFERROR(SUMIFS('Evaluación escrita'!$E$6:$E$125,'Evaluación escrita'!$A$6:$A$125,A12,'Evaluación escrita'!$T$6:$T$125,"Sí")/B12,"")) | E12: =IF(A12="","",IFERROR(SUMIFS('Evaluación escrita'!$G$6:$G$125,'Evaluación escrita'!$A$6:$A$125,A12,'Evaluación escrita'!$T$6:$T$125,"Sí")/B12,"")) | F12: =IF(A12="","",IFERROR(SUMIFS('Evaluación escrita'!$I$6:$I$125,'Evaluación escrita'!$A$6:$A$125,A12,'Evaluación escrita'!$T$6:$T$125,"Sí")/B12,"")) | G12: =IF(A12="","",IFERROR(SUMIFS('Evaluación escrita'!$K$6:$K$125,'Evaluación escrita'!$A$6:$A$125,A12,'Evaluación escrita'!$T$6:$T$125,"Sí")/B12,"")) | H12: =IF(A12="","",IFERROR(SUMIFS('Evaluación escrita'!$M$6:$M$125,'Evaluación escrita'!$A$6:$A$125,A12,'Evaluación escrita'!$T$6:$T$125,"Sí")/B12,"")) | I12: =IF(A12="","",IF(B12>=Instrucciones!$B30,"Sí","Pendiente")) | J12: =IF(C12="","",RANK(C12,$C$6:$C$65,0))
B13: =IF(A13="","",COUNTIFS('Evaluación escrita'!$A$6:$A$125,A13,'Evaluación escrita'!$T$6:$T$125,"Sí")) | C13: =IF(A13="","",IFERROR(SUMIFS('Evaluación escrita'!$O$6:$O$125,'Evaluación escrita'!$A$6:$A$125,A13,'Evaluación escrita'!$T$6:$T$125,"Sí")/B13,"")) | D13: =IF(A13="","",IFERROR(SUMIFS('Evaluación escrita'!$E$6:$E$125,'Evaluación escrita'!$A$6:$A$125,A13,'Evaluación escrita'!$T$6:$T$125,"Sí")/B13,"")) | E13: =IF(A13="","",IFERROR(SUMIFS('Evaluación escrita'!$G$6:$G$125,'Evaluación escrita'!$A$6:$A$125,A13,'Evaluación escrita'!$T$6:$T$125,"Sí")/B13,"")) | F13: =IF(A13="","",IFERROR(SUMIFS('Evaluación escrita'!$I$6:$I$125,'Evaluación escrita'!$A$6:$A$125,A13,'Evaluación escrita'!$T$6:$T$125,"Sí")/B13,"")) | G13: =IF(A13="","",IFERROR(SUMIFS('Evaluación escrita'!$K$6:$K$125,'Evaluación escrita'!$A$6:$A$125,A13,'Evaluación escrita'!$T$6:$T$125,"Sí")/B13,"")) | H13: =IF(A13="","",IFERROR(SUMIFS('Evaluación escrita'!$M$6:$M$125,'Evaluación escrita'!$A$6:$A$125,A13,'Evaluación escrita'!$T$6:$T$125,"Sí")/B13,"")) | I13: =IF(A13="","",IF(B13>=Instrucciones!$B31,"Sí","Pendiente")) | J13: =IF(C13="","",RANK(C13,$C$6:$C$65,0))
B14: =IF(A14="","",COUNTIFS('Evaluación escrita'!$A$6:$A$125,A14,'Evaluación escrita'!$T$6:$T$125,"Sí")) | C14: =IF(A14="","",IFERROR(SUMIFS('Evaluación escrita'!$O$6:$O$125,'Evaluación escrita'!$A$6:$A$125,A14,'Evaluación escrita'!$T$6:$T$125,"Sí")/B14,"")) | D14: =IF(A14="","",IFERROR(SUMIFS('Evaluación escrita'!$E$6:$E$125,'Evaluación escrita'!$A$6:$A$125,A14,'Evaluación escrita'!$T$6:$T$125,"Sí")/B14,"")) | E14: =IF(A14="","",IFERROR(SUMIFS('Evaluación escrita'!$G$6:$G$125,'Evaluación escrita'!$A$6:$A$125,A14,'Evaluación escrita'!$T$6:$T$125,"Sí")/B14,"")) | F14: =IF(A14="","",IFERROR(SUMIFS('Evaluación escrita'!$I$6:$I$125,'Evaluación escrita'!$A$6:$A$125,A14,'Evaluación escrita'!$T$6:$T$125,"Sí")/B14,"")) | G14: =IF(A14="","",IFERROR(SUMIFS('Evaluación escrita'!$K$6:$K$125,'Evaluación escrita'!$A$6:$A$125,A14,'Evaluación escrita'!$T$6:$T$125,"Sí")/B14,"")) | H14: =IF(A14="","",IFERROR(SUMIFS('Evaluación escrita'!$M$6:$M$125,'Evaluación escrita'!$A$6:$A$125,A14,'Evaluación escrita'!$T$6:$T$125,"Sí")/B14,"")) | I14: =IF(A14="","",IF(B14>=Instrucciones!$B32,"Sí","Pendiente")) | J14: =IF(C14="","",RANK(C14,$C$6:$C$65,0))
B15: =IF(A15="","",COUNTIFS('Evaluación escrita'!$A$6:$A$125,A15,'Evaluación escrita'!$T$6:$T$125,"Sí")) | C15: =IF(A15="","",IFERROR(SUMIFS('Evaluación escrita'!$O$6:$O$125,'Evaluación escrita'!$A$6:$A$125,A15,'Evaluación escrita'!$T$6:$T$125,"Sí")/B15,"")) | D15: =IF(A15="","",IFERROR(SUMIFS('Evaluación escrita'!$E$6:$E$125,'Evaluación escrita'!$A$6:$A$125,A15,'Evaluación escrita'!$T$6:$T$125,"Sí")/B15,"")) | E15: =IF(A15="","",IFERROR(SUMIFS('Evaluación escrita'!$G$6:$G$125,'Evaluación escrita'!$A$6:$A$125,A15,'Evaluación escrita'!$T$6:$T$125,"Sí")/B15,"")) | F15: =IF(A15="","",IFERROR(SUMIFS('Evaluación escrita'!$I$6:$I$125,'Evaluación escrita'!$A$6:$A$125,A15,'Evaluación escrita'!$T$6:$T$125,"Sí")/B15,"")) | G15: =IF(A15="","",IFERROR(SUMIFS('Evaluación escrita'!$K$6:$K$125,'Evaluación escrita'!$A$6:$A$125,A15,'Evaluación escrita'!$T$6:$T$125,"Sí")/B15,"")) | H15: =IF(A15="","",IFERROR(SUMIFS('Evaluación escrita'!$M$6:$M$125,'Evaluación escrita'!$A$6:$A$125,A15,'Evaluación escrita'!$T$6:$T$125,"Sí")/B15,"")) | I15: =IF(A15="","",IF(B15>=Instrucciones!$B33,"Sí","Pendiente")) | J15: =IF(C15="","",RANK(C15,$C$6:$C$65,0))
B16: =IF(A16="","",COUNTIFS('Evaluación escrita'!$A$6:$A$125,A16,'Evaluación escrita'!$T$6:$T$125,"Sí")) | C16: =IF(A16="","",IFERROR(SUMIFS('Evaluación escrita'!$O$6:$O$125,'Evaluación escrita'!$A$6:$A$125,A16,'Evaluación escrita'!$T$6:$T$125,"Sí")/B16,"")) | D16: =IF(A16="","",IFERROR(SUMIFS('Evaluación escrita'!$E$6:$E$125,'Evaluación escrita'!$A$6:$A$125,A16,'Evaluación escrita'!$T$6:$T$125,"Sí")/B16,"")) | E16: =IF(A16="","",IFERROR(SUMIFS('Evaluación escrita'!$G$6:$G$125,'Evaluación escrita'!$A$6:$A$125,A16,'Evaluación escrita'!$T$6:$T$125,"Sí")/B16,"")) | F16: =IF(A16="","",IFERROR(SUMIFS('Evaluación escrita'!$I$6:$I$125,'Evaluación escrita'!$A$6:$A$125,A16,'Evaluación escrita'!$T$6:$T$125,"Sí")/B16,"")) | G16: =IF(A16="","",IFERROR(SUMIFS('Evaluación escrita'!$K$6:$K$125,'Evaluación escrita'!$A$6:$A$125,A16,'Evaluación escrita'!$T$6:$T$125,"Sí")/B16,"")) | H16: =IF(A16="","",IFERROR(SUMIFS('Evaluación escrita'!$M$6:$M$125,'Evaluación escrita'!$A$6:$A$125,A16,'Evaluación escrita'!$T$6:$T$125,"Sí")/B16,"")) | I16: =IF(A16="","",IF(B16>=Instrucciones!$B34,"Sí","Pendiente")) | J16: =IF(C16="","",RANK(C16,$C$6:$C$65,0))
B17: =IF(A17="","",COUNTIFS('Evaluación escrita'!$A$6:$A$125,A17,'Evaluación escrita'!$T$6:$T$125,"Sí")) | C17: =IF(A17="","",IFERROR(SUMIFS('Evaluación escrita'!$O$6:$O$125,'Evaluación escrita'!$A$6:$A$125,A17,'Evaluación escrita'!$T$6:$T$125,"Sí")/B17,"")) | D17: =IF(A17="","",IFERROR(SUMIFS('Evaluación escrita'!$E$6:$E$125,'Evaluación escrita'!$A$6:$A$125,A17,'Evaluación escrita'!$T$6:$T$125,"Sí")/B17,"")) | E17: =IF(A17="","",IFERROR(SUMIFS('Evaluación escrita'!$G$6:$G$125,'Evaluación escrita'!$A$6:$A$125,A17,'Evaluación escrita'!$T$6:$T$125,"Sí")/B17,"")) | F17: =IF(A17="","",IFERROR(SUMIFS('Evaluación escrita'!$I$6:$I$125,'Evaluación escrita'!$A$6:$A$125,A17,'Evaluación escrita'!$T$6:$T$125,"Sí")/B17,"")) | G17: =IF(A17="","",IFERROR(SUMIFS('Evaluación escrita'!$K$6:$K$125,'Evaluación escrita'!$A$6:$A$125,A17,'Evaluación escrita'!$T$6:$T$125,"Sí")/B17,"")) | H17: =IF(A17="","",IFERROR(SUMIFS('Evaluación escrita'!$M$6:$M$125,'Evaluación escrita'!$A$6:$A$125,A17,'Evaluación escrita'!$T$6:$T$125,"Sí")/B17,"")) | I17: =IF(A17="","",IF(B17>=Instrucciones!$B35,"Sí","Pendiente")) | J17: =IF(C17="","",RANK(C17,$C$6:$C$65,0))
B18: =IF(A18="","",COUNTIFS('Evaluación escrita'!$A$6:$A$125,A18,'Evaluación escrita'!$T$6:$T$125,"Sí")) | C18: =IF(A18="","",IFERROR(SUMIFS('Evaluación escrita'!$O$6:$O$125,'Evaluación escrita'!$A$6:$A$125,A18,'Evaluación escrita'!$T$6:$T$125,"Sí")/B18,"")) | D18: =IF(A18="","",IFERROR(SUMIFS('Evaluación escrita'!$E$6:$E$125,'Evaluación escrita'!$A$6:$A$125,A18,'Evaluación escrita'!$T$6:$T$125,"Sí")/B18,"")) | E18: =IF(A18="","",IFERROR(SUMIFS('Evaluación escrita'!$G$6:$G$125,'Evaluación escrita'!$A$6:$A$125,A18,'Evaluación escrita'!$T$6:$T$125,"Sí")/B18,"")) | F18: =IF(A18="","",IFERROR(SUMIFS('Evaluación escrita'!$I$6:$I$125,'Evaluación escrita'!$A$6:$A$125,A18,'Evaluación escrita'!$T$6:$T$125,"Sí")/B18,"")) | G18: =IF(A18="","",IFERROR(SUMIFS('Evaluación escrita'!$K$6:$K$125,'Evaluación escrita'!$A$6:$A$125,A18,'Evaluación escrita'!$T$6:$T$125,"Sí")/B18,"")) | H18: =IF(A18="","",IFERROR(SUMIFS('Evaluación escrita'!$M$6:$M$125,'Evaluación escrita'!$A$6:$A$125,A18,'Evaluación escrita'!$T$6:$T$125,"Sí")/B18,"")) | I18: =IF(A18="","",IF(B18>=Instrucciones!$B36,"Sí","Pendiente")) | J18: =IF(C18="","",RANK(C18,$C$6:$C$65,0))
B19: =IF(A19="","",COUNTIFS('Evaluación escrita'!$A$6:$A$125,A19,'Evaluación escrita'!$T$6:$T$125,"Sí")) | C19: =IF(A19="","",IFERROR(SUMIFS('Evaluación escrita'!$O$6:$O$125,'Evaluación escrita'!$A$6:$A$125,A19,'Evaluación escrita'!$T$6:$T$125,"Sí")/B19,"")) | D19: =IF(A19="","",IFERROR(SUMIFS('Evaluación escrita'!$E$6:$E$125,'Evaluación escrita'!$A$6:$A$125,A19,'Evaluación escrita'!$T$6:$T$125,"Sí")/B19,"")) | E19: =IF(A19="","",IFERROR(SUMIFS('Evaluación escrita'!$G$6:$G$125,'Evaluación escrita'!$A$6:$A$125,A19,'Evaluación escrita'!$T$6:$T$125,"Sí")/B19,"")) | F19: =IF(A19="","",IFERROR(SUMIFS('Evaluación escrita'!$I$6:$I$125,'Evaluación escrita'!$A$6:$A$125,A19,'Evaluación escrita'!$T$6:$T$125,"Sí")/B19,"")) | G19: =IF(A19="","",IFERROR(SUMIFS('Evaluación escrita'!$K$6:$K$125,'Evaluación escrita'!$A$6:$A$125,A19,'Evaluación escrita'!$T$6:$T$125,"Sí")/B19,"")) | H19: =IF(A19="","",IFERROR(SUMIFS('Evaluación escrita'!$M$6:$M$125,'Evaluación escrita'!$A$6:$A$125,A19,'Evaluación escrita'!$T$6:$T$125,"Sí")/B19,"")) | I19: =IF(A19="","",IF(B19>=Instrucciones!$B37,"Sí","Pendiente")) | J19: =IF(C19="","",RANK(C19,$C$6:$C$65,0))
... B65: =IF(A65="","",COUNTIFS('Evaluación escrita'!$A$6:$A$125,A65,'Evaluación escrita'!$T$6:$T$125,"Sí")) | C65: =IF(A65="","",IFERROR(SUMIFS('Evaluación escrita'!$O$6:$O$125,'Evaluación escrita'!$A$6:$A$125,A65,'Evaluación escrita'!$T$6:$T$125,"Sí")/B65,"")) | D65: =IF(A65="","",IFERROR(SUMIFS('Evaluación escrita'!$E$6:$E$125,'Evaluación escrita'!$A$6:$A$125,A65,'Evaluación escrita'!$T$6:$T$125,"Sí")/B65,"")) | E65: =IF(A65="","",IFERROR(SUMIFS('Evaluación escrita'!$G$6:$G$125,'Evaluación escrita'!$A$6:$A$125,A65,'Evaluación escrita'!$T$6:$T$125,"Sí")/B65,"")) | F65: =IF(A65="","",IFERROR(SUMIFS('Evaluación escrita'!$I$6:$I$125,'Evaluación escrita'!$A$6:$A$125,A65,'Evaluación escrita'!$T$6:$T$125,"Sí")/B65,"")) | G65: =IF(A65="","",IFERROR(SUMIFS('Evaluación escrita'!$K$6:$K$125,'Evaluación escrita'!$A$6:$A$125,A65,'Evaluación escrita'!$T$6:$T$125,"Sí")/B65,"")) | H65: =IF(A65="","",IFERROR(SUMIFS('Evaluación escrita'!$M$6:$M$125,'Evaluación escrita'!$A$6:$A$125,A65,'Evaluación escrita'!$T$6:$T$125,"Sí")/B65,"")) | I65: =IF(A65="","",IF(B65>=Instrucciones!$B83,"Sí","Pendiente")) | J65: =IF(C65="","",RANK(C65,$C$6:$C$65,0))

Sheet Consolidado final
A1: Consolidado final | M1: Criterios y máximos
M2: Clave | N2: Criterio | O2: Máximo
A3: Capture en la columna A los folios que participan en esta etapa. Los demás campos se calculan automáticamente a partir de las evaluaciones válidas. | M3: C1 | N3: Solidez y coherencia del argumento | O3: 25
M4: C2 | N4: Uso de evidencia y respuesta a objeciones | O4: 25
A5: Folio del equipo | B5: Evaluaciones válidas | C5: Promedio total | D5: Promedio C1 | E5: Promedio C2 | F5: Promedio C3 | G5: Promedio C4 | H5: Promedio C5 | I5: Evaluación completa | J5: Lugar preliminar | K5: Observación de coordinación | M5: C3 | N5: Claridad y estructura de la presentación | O5: 20
B6: =IF(A6="","",COUNTIFS('Final presencial'!$A$6:$A$125,A6,'Final presencial'!$T$6:$T$125,"Sí")) | C6: =IF(A6="","",IFERROR(SUMIFS('Final presencial'!$O$6:$O$125,'Final presencial'!$A$6:$A$125,A6,'Final presencial'!$T$6:$T$125,"Sí")/B6,"")) | D6: =IF(A6="","",IFERROR(SUMIFS('Final presencial'!$E$6:$E$125,'Final presencial'!$A$6:$A$125,A6,'Final presencial'!$T$6:$T$125,"Sí")/B6,"")) | E6: =IF(A6="","",IFERROR(SUMIFS('Final presencial'!$G$6:$G$125,'Final presencial'!$A$6:$A$125,A6,'Final presencial'!$T$6:$T$125,"Sí")/B6,"")) | F6: =IF(A6="","",IFERROR(SUMIFS('Final presencial'!$I$6:$I$125,'Final presencial'!$A$6:$A$125,A6,'Final presencial'!$T$6:$T$125,"Sí")/B6,"")) | G6: =IF(A6="","",IFERROR(SUMIFS('Final presencial'!$K$6:$K$125,'Final presencial'!$A$6:$A$125,A6,'Final presencial'!$T$6:$T$125,"Sí")/B6,"")) | H6: =IF(A6="","",IFERROR(SUMIFS('Final presencial'!$M$6:$M$125,'Final presencial'!$A$6:$A$125,A6,'Final presencial'!$T$6:$T$125,"Sí")/B6,"")) | I6: =IF(A6="","",IF(B6>=Instrucciones!$B25,"Sí","Pendiente")) | J6: =IF(C6="","",RANK(C6,$C$6:$C$65,0)) | M6: C4 | N6: Defensa ante las preguntas del jurado | O6: 20
B7: =IF(A7="","",COUNTIFS('Final presencial'!$A$6:$A$125,A7,'Final presencial'!$T$6:$T$125,"Sí")) | C7: =IF(A7="","",IFERROR(SUMIFS('Final presencial'!$O$6:$O$125,'Final presencial'!$A$6:$A$125,A7,'Final presencial'!$T$6:$T$125,"Sí")/B7,"")) | D7: =IF(A7="","",IFERROR(SUMIFS('Final presencial'!$E$6:$E$125,'Final presencial'!$A$6:$A$125,A7,'Final presencial'!$T$6:$T$125,"Sí")/B7,"")) | E7: =IF(A7="","",IFERROR(SUMIFS('Final presencial'!$G$6:$G$125,'Final presencial'!$A$6:$A$125,A7,'Final presencial'!$T$6:$T$125,"Sí")/B7,"")) | F7: =IF(A7="","",IFERROR(SUMIFS('Final presencial'!$I$6:$I$125,'Final presencial'!$A$6:$A$125,A7,'Final presencial'!$T$6:$T$125,"Sí")/B7,"")) | G7: =IF(A7="","",IFERROR(SUMIFS('Final presencial'!$K$6:$K$125,'Final presencial'!$A$6:$A$125,A7,'Final presencial'!$T$6:$T$125,"Sí")/B7,"")) | H7: =IF(A7="","",IFERROR(SUMIFS('Final presencial'!$M$6:$M$125,'Final presencial'!$A$6:$A$125,A7,'Final presencial'!$T$6:$T$125,"Sí")/B7,"")) | I7: =IF(A7="","",IF(B7>=Instrucciones!$B26,"Sí","Pendiente")) | J7: =IF(C7="","",RANK(C7,$C$6:$C$65,0)) | M7: C5 | N7: Participación y coordinación del equipo | O7: 10
B8: =IF(A8="","",COUNTIFS('Final presencial'!$A$6:$A$125,A8,'Final presencial'!$T$6:$T$125,"Sí")) | C8: =IF(A8="","",IFERROR(SUMIFS('Final presencial'!$O$6:$O$125,'Final presencial'!$A$6:$A$125,A8,'Final presencial'!$T$6:$T$125,"Sí")/B8,"")) | D8: =IF(A8="","",IFERROR(SUMIFS('Final presencial'!$E$6:$E$125,'Final presencial'!$A$6:$A$125,A8,'Final presencial'!$T$6:$T$125,"Sí")/B8,"")) | E8: =IF(A8="","",IFERROR(SUMIFS('Final presencial'!$G$6:$G$125,'Final presencial'!$A$6:$A$125,A8,'Final presencial'!$T$6:$T$125,"Sí")/B8,"")) | F8: =IF(A8="","",IFERROR(SUMIFS('Final presencial'!$I$6:$I$125,'Final presencial'!$A$6:$A$125,A8,'Final presencial'!$T$6:$T$125,"Sí")/B8,"")) | G8: =IF(A8="","",IFERROR(SUMIFS('Final presencial'!$K$6:$K$125,'Final presencial'!$A$6:$A$125,A8,'Final presencial'!$T$6:$T$125,"Sí")/B8,"")) | H8: =IF(A8="","",IFERROR(SUMIFS('Final presencial'!$M$6:$M$125,'Final presencial'!$A$6:$A$125,A8,'Final presencial'!$T$6:$T$125,"Sí")/B8,"")) | I8: =IF(A8="","",IF(B8>=Instrucciones!$B27,"Sí","Pendiente")) | J8: =IF(C8="","",RANK(C8,$C$6:$C$65,0))
B9: =IF(A9="","",COUNTIFS('Final presencial'!$A$6:$A$125,A9,'Final presencial'!$T$6:$T$125,"Sí")) | C9: =IF(A9="","",IFERROR(SUMIFS('Final presencial'!$O$6:$O$125,'Final presencial'!$A$6:$A$125,A9,'Final presencial'!$T$6:$T$125,"Sí")/B9,"")) | D9: =IF(A9="","",IFERROR(SUMIFS('Final presencial'!$E$6:$E$125,'Final presencial'!$A$6:$A$125,A9,'Final presencial'!$T$6:$T$125,"Sí")/B9,"")) | E9: =IF(A9="","",IFERROR(SUMIFS('Final presencial'!$G$6:$G$125,'Final presencial'!$A$6:$A$125,A9,'Final presencial'!$T$6:$T$125,"Sí")/B9,"")) | F9: =IF(A9="","",IFERROR(SUMIFS('Final presencial'!$I$6:$I$125,'Final presencial'!$A$6:$A$125,A9,'Final presencial'!$T$6:$T$125,"Sí")/B9,"")) | G9: =IF(A9="","",IFERROR(SUMIFS('Final presencial'!$K$6:$K$125,'Final presencial'!$A$6:$A$125,A9,'Final presencial'!$T$6:$T$125,"Sí")/B9,"")) | H9: =IF(A9="","",IFERROR(SUMIFS('Final presencial'!$M$6:$M$125,'Final presencial'!$A$6:$A$125,A9,'Final presencial'!$T$6:$T$125,"Sí")/B9,"")) | I9: =IF(A9="","",IF(B9>=Instrucciones!$B28,"Sí","Pendiente")) | J9: =IF(C9="","",RANK(C9,$C$6:$C$65,0))
B10: =IF(A10="","",COUNTIFS('Final presencial'!$A$6:$A$125,A10,'Final presencial'!$T$6:$T$125,"Sí")) | C10: =IF(A10="","",IFERROR(SUMIFS('Final presencial'!$O$6:$O$125,'Final presencial'!$A$6:$A$125,A10,'Final presencial'!$T$6:$T$125,"Sí")/B10,"")) | D10: =IF(A10="","",IFERROR(SUMIFS('Final presencial'!$E$6:$E$125,'Final presencial'!$A$6:$A$125,A10,'Final presencial'!$T$6:$T$125,"Sí")/B10,"")) | E10: =IF(A10="","",IFERROR(SUMIFS('Final presencial'!$G$6:$G$125,'Final presencial'!$A$6:$A$125,A10,'Final presencial'!$T$6:$T$125,"Sí")/B10,"")) | F10: =IF(A10="","",IFERROR(SUMIFS('Final presencial'!$I$6:$I$125,'Final presencial'!$A$6:$A$125,A10,'Final presencial'!$T$6:$T$125,"Sí")/B10,"")) | G10: =IF(A10="","",IFERROR(SUMIFS('Final presencial'!$K$6:$K$125,'Final presencial'!$A$6:$A$125,A10,'Final presencial'!$T$6:$T$125,"Sí")/B10,"")) | H10: =IF(A10="","",IFERROR(SUMIFS('Final presencial'!$M$6:$M$125,'Final presencial'!$A$6:$A$125,A10,'Final presencial'!$T$6:$T$125,"Sí")/B10,"")) | I10: =IF(A10="","",IF(B10>=Instrucciones!$B29,"Sí","Pendiente")) | J10: =IF(C10="","",RANK(C10,$C$6:$C$65,0))
B11: =IF(A11="","",COUNTIFS('Final presencial'!$A$6:$A$125,A11,'Final presencial'!$T$6:$T$125,"Sí")) | C11: =IF(A11="","",IFERROR(SUMIFS('Final presencial'!$O$6:$O$125,'Final presencial'!$A$6:$A$125,A11,'Final presencial'!$T$6:$T$125,"Sí")/B11,"")) | D11: =IF(A11="","",IFERROR(SUMIFS('Final presencial'!$E$6:$E$125,'Final presencial'!$A$6:$A$125,A11,'Final presencial'!$T$6:$T$125,"Sí")/B11,"")) | E11: =IF(A11="","",IFERROR(SUMIFS('Final presencial'!$G$6:$G$125,'Final presencial'!$A$6:$A$125,A11,'Final presencial'!$T$6:$T$125,"Sí")/B11,"")) | F11: =IF(A11="","",IFERROR(SUMIFS('Final presencial'!$I$6:$I$125,'Final presencial'!$A$6:$A$125,A11,'Final presencial'!$T$6:$T$125,"Sí")/B11,"")) | G11: =IF(A11="","",IFERROR(SUMIFS('Final presencial'!$K$6:$K$125,'Final presencial'!$A$6:$A$125,A11,'Final presencial'!$T$6:$T$125,"Sí")/B11,"")) | H11: =IF(A11="","",IFERROR(SUMIFS('Final presencial'!$M$6:$M$125,'Final presencial'!$A$6:$A$125,A11,'Final presencial'!$T$6:$T$125,"Sí")/B11,"")) | I11: =IF(A11="","",IF(B11>=Instrucciones!$B30,"Sí","Pendiente")) | J11: =IF(C11="","",RANK(C11,$C$6:$C$65,0))
B12: =IF(A12="","",COUNTIFS('Final presencial'!$A$6:$A$125,A12,'Final presencial'!$T$6:$T$125,"Sí")) | C12: =IF(A12="","",IFERROR(SUMIFS('Final presencial'!$O$6:$O$125,'Final presencial'!$A$6:$A$125,A12,'Final presencial'!$T$6:$T$125,"Sí")/B12,"")) | D12: =IF(A12="","",IFERROR(SUMIFS('Final presencial'!$E$6:$E$125,'Final presencial'!$A$6:$A$125,A12,'Final presencial'!$T$6:$T$125,"Sí")/B12,"")) | E12: =IF(A12="","",IFERROR(SUMIFS('Final presencial'!$G$6:$G$125,'Final presencial'!$A$6:$A$125,A12,'Final presencial'!$T$6:$T$125,"Sí")/B12,"")) | F12: =IF(A12="","",IFERROR(SUMIFS('Final presencial'!$I$6:$I$125,'Final presencial'!$A$6:$A$125,A12,'Final presencial'!$T$6:$T$125,"Sí")/B12,"")) | G12: =IF(A12="","",IFERROR(SUMIFS('Final presencial'!$K$6:$K$125,'Final presencial'!$A$6:$A$125,A12,'Final presencial'!$T$6:$T$125,"Sí")/B12,"")) | H12: =IF(A12="","",IFERROR(SUMIFS('Final presencial'!$M$6:$M$125,'Final presencial'!$A$6:$A$125,A12,'Final presencial'!$T$6:$T$125,"Sí")/B12,"")) | I12: =IF(A12="","",IF(B12>=Instrucciones!$B31,"Sí","Pendiente")) | J12: =IF(C12="","",RANK(C12,$C$6:$C$65,0))
B13: =IF(A13="","",COUNTIFS('Final presencial'!$A$6:$A$125,A13,'Final presencial'!$T$6:$T$125,"Sí")) | C13: =IF(A13="","",IFERROR(SUMIFS('Final presencial'!$O$6:$O$125,'Final presencial'!$A$6:$A$125,A13,'Final presencial'!$T$6:$T$125,"Sí")/B13,"")) | D13: =IF(A13="","",IFERROR(SUMIFS('Final presencial'!$E$6:$E$125,'Final presencial'!$A$6:$A$125,A13,'Final presencial'!$T$6:$T$125,"Sí")/B13,"")) | E13: =IF(A13="","",IFERROR(SUMIFS('Final presencial'!$G$6:$G$125,'Final presencial'!$A$6:$A$125,A13,'Final presencial'!$T$6:$T$125,"Sí")/B13,"")) | F13: =IF(A13="","",IFERROR(SUMIFS('Final presencial'!$I$6:$I$125,'Final presencial'!$A$6:$A$125,A13,'Final presencial'!$T$6:$T$125,"Sí")/B13,"")) | G13: =IF(A13="","",IFERROR(SUMIFS('Final presencial'!$K$6:$K$125,'Final presencial'!$A$6:$A$125,A13,'Final presencial'!$T$6:$T$125,"Sí")/B13,"")) | H13: =IF(A13="","",IFERROR(SUMIFS('Final presencial'!$M$6:$M$125,'Final presencial'!$A$6:$A$125,A13,'Final presencial'!$T$6:$T$125,"Sí")/B13,"")) | I13: =IF(A13="","",IF(B13>=Instrucciones!$B32,"Sí","Pendiente")) | J13: =IF(C13="","",RANK(C13,$C$6:$C$65,0))
B14: =IF(A14="","",COUNTIFS('Final presencial'!$A$6:$A$125,A14,'Final presencial'!$T$6:$T$125,"Sí")) | C14: =IF(A14="","",IFERROR(SUMIFS('Final presencial'!$O$6:$O$125,'Final presencial'!$A$6:$A$125,A14,'Final presencial'!$T$6:$T$125,"Sí")/B14,"")) | D14: =IF(A14="","",IFERROR(SUMIFS('Final presencial'!$E$6:$E$125,'Final presencial'!$A$6:$A$125,A14,'Final presencial'!$T$6:$T$125,"Sí")/B14,"")) | E14: =IF(A14="","",IFERROR(SUMIFS('Final presencial'!$G$6:$G$125,'Final presencial'!$A$6:$A$125,A14,'Final presencial'!$T$6:$T$125,"Sí")/B14,"")) | F14: =IF(A14="","",IFERROR(SUMIFS('Final presencial'!$I$6:$I$125,'Final presencial'!$A$6:$A$125,A14,'Final presencial'!$T$6:$T$125,"Sí")/B14,"")) | G14: =IF(A14="","",IFERROR(SUMIFS('Final presencial'!$K$6:$K$125,'Final presencial'!$A$6:$A$125,A14,'Final presencial'!$T$6:$T$125,"Sí")/B14,"")) | H14: =IF(A14="","",IFERROR(SUMIFS('Final presencial'!$M$6:$M$125,'Final presencial'!$A$6:$A$125,A14,'Final presencial'!$T$6:$T$125,"Sí")/B14,"")) | I14: =IF(A14="","",IF(B14>=Instrucciones!$B33,"Sí","Pendiente")) | J14: =IF(C14="","",RANK(C14,$C$6:$C$65,0))
B15: =IF(A15="","",COUNTIFS('Final presencial'!$A$6:$A$125,A15,'Final presencial'!$T$6:$T$125,"Sí")) | C15: =IF(A15="","",IFERROR(SUMIFS('Final presencial'!$O$6:$O$125,'Final presencial'!$A$6:$A$125,A15,'Final presencial'!$T$6:$T$125,"Sí")/B15,"")) | D15: =IF(A15="","",IFERROR(SUMIFS('Final presencial'!$E$6:$E$125,'Final presencial'!$A$6:$A$125,A15,'Final presencial'!$T$6:$T$125,"Sí")/B15,"")) | E15: =IF(A15="","",IFERROR(SUMIFS('Final presencial'!$G$6:$G$125,'Final presencial'!$A$6:$A$125,A15,'Final presencial'!$T$6:$T$125,"Sí")/B15,"")) | F15: =IF(A15="","",IFERROR(SUMIFS('Final presencial'!$I$6:$I$125,'Final presencial'!$A$6:$A$125,A15,'Final presencial'!$T$6:$T$125,"Sí")/B15,"")) | G15: =IF(A15="","",IFERROR(SUMIFS('Final presencial'!$K$6:$K$125,'Final presencial'!$A$6:$A$125,A15,'Final presencial'!$T$6:$T$125,"Sí")/B15,"")) | H15: =IF(A15="","",IFERROR(SUMIFS('Final presencial'!$M$6:$M$125,'Final presencial'!$A$6:$A$125,A15,'Final presencial'!$T$6:$T$125,"Sí")/B15,"")) | I15: =IF(A15="","",IF(B15>=Instrucciones!$B34,"Sí","Pendiente")) | J15: =IF(C15="","",RANK(C15,$C$6:$C$65,0))
B16: =IF(A16="","",COUNTIFS('Final presencial'!$A$6:$A$125,A16,'Final presencial'!$T$6:$T$125,"Sí")) | C16: =IF(A16="","",IFERROR(SUMIFS('Final presencial'!$O$6:$O$125,'Final presencial'!$A$6:$A$125,A16,'Final presencial'!$T$6:$T$125,"Sí")/B16,"")) | D16: =IF(A16="","",IFERROR(SUMIFS('Final presencial'!$E$6:$E$125,'Final presencial'!$A$6:$A$125,A16,'Final presencial'!$T$6:$T$125,"Sí")/B16,"")) | E16: =IF(A16="","",IFERROR(SUMIFS('Final presencial'!$G$6:$G$125,'Final presencial'!$A$6:$A$125,A16,'Final presencial'!$T$6:$T$125,"Sí")/B16,"")) | F16: =IF(A16="","",IFERROR(SUMIFS('Final presencial'!$I$6:$I$125,'Final presencial'!$A$6:$A$125,A16,'Final presencial'!$T$6:$T$125,"Sí")/B16,"")) | G16: =IF(A16="","",IFERROR(SUMIFS('Final presencial'!$K$6:$K$125,'Final presencial'!$A$6:$A$125,A16,'Final presencial'!$T$6:$T$125,"Sí")/B16,"")) | H16: =IF(A16="","",IFERROR(SUMIFS('Final presencial'!$M$6:$M$125,'Final presencial'!$A$6:$A$125,A16,'Final presencial'!$T$6:$T$125,"Sí")/B16,"")) | I16: =IF(A16="","",IF(B16>=Instrucciones!$B35,"Sí","Pendiente")) | J16: =IF(C16="","",RANK(C16,$C$6:$C$65,0))
B17: =IF(A17="","",COUNTIFS('Final presencial'!$A$6:$A$125,A17,'Final presencial'!$T$6:$T$125,"Sí")) | C17: =IF(A17="","",IFERROR(SUMIFS('Final presencial'!$O$6:$O$125,'Final presencial'!$A$6:$A$125,A17,'Final presencial'!$T$6:$T$125,"Sí")/B17,"")) | D17: =IF(A17="","",IFERROR(SUMIFS('Final presencial'!$E$6:$E$125,'Final presencial'!$A$6:$A$125,A17,'Final presencial'!$T$6:$T$125,"Sí")/B17,"")) | E17: =IF(A17="","",IFERROR(SUMIFS('Final presencial'!$G$6:$G$125,'Final presencial'!$A$6:$A$125,A17,'Final presencial'!$T$6:$T$125,"Sí")/B17,"")) | F17: =IF(A17="","",IFERROR(SUMIFS('Final presencial'!$I$6:$I$125,'Final presencial'!$A$6:$A$125,A17,'Final presencial'!$T$6:$T$125,"Sí")/B17,"")) | G17: =IF(A17="","",IFERROR(SUMIFS('Final presencial'!$K$6:$K$125,'Final presencial'!$A$6:$A$125,A17,'Final presencial'!$T$6:$T$125,"Sí")/B17,"")) | H17: =IF(A17="","",IFERROR(SUMIFS('Final presencial'!$M$6:$M$125,'Final presencial'!$A$6:$A$125,A17,'Final presencial'!$T$6:$T$125,"Sí")/B17,"")) | I17: =IF(A17="","",IF(B17>=Instrucciones!$B36,"Sí","Pendiente")) | J17: =IF(C17="","",RANK(C17,$C$6:$C$65,0))
B18: =IF(A18="","",COUNTIFS('Final presencial'!$A$6:$A$125,A18,'Final presencial'!$T$6:$T$125,"Sí")) | C18: =IF(A18="","",IFERROR(SUMIFS('Final presencial'!$O$6:$O$125,'Final presencial'!$A$6:$A$125,A18,'Final presencial'!$T$6:$T$125,"Sí")/B18,"")) | D18: =IF(A18="","",IFERROR(SUMIFS('Final presencial'!$E$6:$E$125,'Final presencial'!$A$6:$A$125,A18,'Final presencial'!$T$6:$T$125,"Sí")/B18,"")) | E18: =IF(A18="","",IFERROR(SUMIFS('Final presencial'!$G$6:$G$125,'Final presencial'!$A$6:$A$125,A18,'Final presencial'!$T$6:$T$125,"Sí")/B18,"")) | F18: =IF(A18="","",IFERROR(SUMIFS('Final presencial'!$I$6:$I$125,'Final presencial'!$A$6:$A$125,A18,'Final presencial'!$T$6:$T$125,"Sí")/B18,"")) | G18: =IF(A18="","",IFERROR(SUMIFS('Final presencial'!$K$6:$K$125,'Final presencial'!$A$6:$A$125,A18,'Final presencial'!$T$6:$T$125,"Sí")/B18,"")) | H18: =IF(A18="","",IFERROR(SUMIFS('Final presencial'!$M$6:$M$125,'Final presencial'!$A$6:$A$125,A18,'Final presencial'!$T$6:$T$125,"Sí")/B18,"")) | I18: =IF(A18="","",IF(B18>=Instrucciones!$B37,"Sí","Pendiente")) | J18: =IF(C18="","",RANK(C18,$C$6:$C$65,0))
B19: =IF(A19="","",COUNTIFS('Final presencial'!$A$6:$A$125,A19,'Final presencial'!$T$6:$T$125,"Sí")) | C19: =IF(A19="","",IFERROR(SUMIFS('Final presencial'!$O$6:$O$125,'Final presencial'!$A$6:$A$125,A19,'Final presencial'!$T$6:$T$125,"Sí")/B19,"")) | D19: =IF(A19="","",IFERROR(SUMIFS('Final presencial'!$E$6:$E$125,'Final presencial'!$A$6:$A$125,A19,'Final presencial'!$T$6:$T$125,"Sí")/B19,"")) | E19: =IF(A19="","",IFERROR(SUMIFS('Final presencial'!$G$6:$G$125,'Final presencial'!$A$6:$A$125,A19,'Final presencial'!$T$6:$T$125,"Sí")/B19,"")) | F19: =IF(A19="","",IFERROR(SUMIFS('Final presencial'!$I$6:$I$125,'Final presencial'!$A$6:$A$125,A19,'Final presencial'!$T$6:$T$125,"Sí")/B19,"")) | G19: =IF(A19="","",IFERROR(SUMIFS('Final presencial'!$K$6:$K$125,'Final presencial'!$A$6:$A$125,A19,'Final presencial'!$T$6:$T$125,"Sí")/B19,"")) | H19: =IF(A19="","",IFERROR(SUMIFS('Final presencial'!$M$6:$M$125,'Final presencial'!$A$6:$A$125,A19,'Final presencial'!$T$6:$T$125,"Sí")/B19,"")) | I19: =IF(A19="","",IF(B19>=Instrucciones!$B38,"Sí","Pendiente")) | J19: =IF(C19="","",RANK(C19,$C$6:$C$65,0))
... B65: =IF(A65="","",COUNTIFS('Final presencial'!$A$6:$A$125,A65,'Final presencial'!$T$6:$T$125,"Sí")) | C65: =IF(A65="","",IFERROR(SUMIFS('Final presencial'!$O$6:$O$125,'Final presencial'!$A$6:$A$125,A65,'Final presencial'!$T$6:$T$125,"Sí")/B65,"")) | D65: =IF(A65="","",IFERROR(SUMIFS('Final presencial'!$E$6:$E$125,'Final presencial'!$A$6:$A$125,A65,'Final presencial'!$T$6:$T$125,"Sí")/B65,"")) | E65: =IF(A65="","",IFERROR(SUMIFS('Final presencial'!$G$6:$G$125,'Final presencial'!$A$6:$A$125,A65,'Final presencial'!$T$6:$T$125,"Sí")/B65,"")) | F65: =IF(A65="","",IFERROR(SUMIFS('Final presencial'!$I$6:$I$125,'Final presencial'!$A$6:$A$125,A65,'Final presencial'!$T$6:$T$125,"Sí")/B65,"")) | G65: =IF(A65="","",IFERROR(SUMIFS('Final presencial'!$K$6:$K$125,'Final presencial'!$A$6:$A$125,A65,'Final presencial'!$T$6:$T$125,"Sí")/B65,"")) | H65: =IF(A65="","",IFERROR(SUMIFS('Final presencial'!$M$6:$M$125,'Final presencial'!$A$6:$A$125,A65,'Final presencial'!$T$6:$T$125,"Sí")/B65,"")) | I65: =IF(A65="","",IF(B65>=Instrucciones!$B84,"Sí","Pendiente")) | J65: =IF(C65="","",RANK(C65,$C$6:$C$65,0))

Sheet Descriptores
A1: Referencia operativa de la rúbrica
